(MainThread:INFO:11/28/2018 10:27:01 AM:33:log_file.py:logging_to_console_and_syslog:hostname=sriramsridhar-HP-EliteBook-8460p
 containerID=
 Setting DOCKER_TAG=ssriram1978,DOCKER_IMAGE_NAME=unit_test
(MainThread:INFO:11/28/2018 10:27:36 AM:33:log_file.py:logging_to_console_and_syslog:hostname=sriramsridhar-HP-EliteBook-8460p
 containerID=
 Setting DOCKER_TAG=ssriram1978,DOCKER_IMAGE_NAME=unit_test
(MainThread:INFO:11/28/2018 10:32:37 AM:33:log_file.py:logging_to_console_and_syslog:hostname=sriramsridhar-HP-EliteBook-8460p
 containerID=
 Setting DOCKER_TAG=ssriram1978,DOCKER_IMAGE_NAME=unit_test
(MainThread:INFO:11/28/2018 10:35:42 AM:33:log_file.py:logging_to_console_and_syslog:hostname=sriramsridhar-HP-EliteBook-8460p
 containerID=
 Setting DOCKER_TAG=ssriram1978,DOCKER_IMAGE_NAME=unit_test
(MainThread:INFO:11/28/2018 10:36:02 AM:33:log_file.py:logging_to_console_and_syslog:hostname=sriramsridhar-HP-EliteBook-8460p
 containerID=
 Setting DOCKER_TAG=ssriram1978,DOCKER_IMAGE_NAME=unit_test
(MainThread:INFO:11/28/2018 10:57:10 AM:33:log_file.py:logging_to_console_and_syslog:hostname=sriramsridhar-HP-EliteBook-8460p
 containerID=
 Setting DOCKER_TAG=ssriram1978,DOCKER_IMAGE_NAME=unit_test
(MainThread:DEBUG:11/28/2018 10:57:10 AM:21:config.py:find_config_file:Trying paths: ['/root/.docker/config.json', '/root/.dockercfg']
(MainThread:DEBUG:11/28/2018 10:57:10 AM:28:config.py:find_config_file:No config file found
(MainThread:DEBUG:11/28/2018 10:57:10 AM:21:config.py:find_config_file:Trying paths: ['/root/.docker/config.json', '/root/.dockercfg']
(MainThread:DEBUG:11/28/2018 10:57:10 AM:28:config.py:find_config_file:No config file found
(MainThread:INFO:11/28/2018 10:57:10 AM:33:log_file.py:logging_to_console_and_syslog:hostname=sriramsridhar-HP-EliteBook-8460p
 containerID=
 Creating Docker image.
(MainThread:INFO:11/28/2018 11:03:46 AM:33:log_file.py:logging_to_console_and_syslog:hostname=sriramsridhar-HP-EliteBook-8460p
 containerID=
 Prune old docker container images.
(MainThread:INFO:11/28/2018 11:03:46 AM:33:log_file.py:logging_to_console_and_syslog:hostname=sriramsridhar-HP-EliteBook-8460p
 containerID=
 Running Docker image.
(MainThread:DEBUG:11/28/2018 11:03:46 AM:396:connectionpool.py:_make_request:http://localhost:None "POST /v1.35/containers/create?name=unit_test HTTP/1.1" 404 58
(MainThread:DEBUG:11/28/2018 11:03:46 AM:41:auth.py:get_config_header:Looking for auth config
(MainThread:DEBUG:11/28/2018 11:03:46 AM:44:auth.py:get_config_header:No auth config in memory - loading from filesystem
(MainThread:DEBUG:11/28/2018 11:03:46 AM:21:config.py:find_config_file:Trying paths: ['/root/.docker/config.json', '/root/.dockercfg']
(MainThread:DEBUG:11/28/2018 11:03:46 AM:28:config.py:find_config_file:No config file found
(MainThread:DEBUG:11/28/2018 11:03:46 AM:104:auth.py:resolve_authconfig:Looking for auth entry for 'docker.io'
(MainThread:DEBUG:11/28/2018 11:03:46 AM:116:auth.py:resolve_authconfig:No entry found
(MainThread:DEBUG:11/28/2018 11:03:46 AM:58:auth.py:get_config_header:No auth config found
(MainThread:DEBUG:11/28/2018 11:03:47 AM:396:connectionpool.py:_make_request:http://localhost:None "POST /v1.35/images/create?tag=latest&fromImage=ssriram1978%2Funit_test HTTP/1.1" 404 116
(MainThread:DEBUG:11/28/2018 11:08:21 AM:21:config.py:find_config_file:Trying paths: ['/root/.docker/config.json', '/root/.dockercfg']
(MainThread:DEBUG:11/28/2018 11:08:21 AM:28:config.py:find_config_file:No config file found
(MainThread:DEBUG:11/28/2018 11:08:21 AM:21:config.py:find_config_file:Trying paths: ['/root/.docker/config.json', '/root/.dockercfg']
(MainThread:DEBUG:11/28/2018 11:08:21 AM:28:config.py:find_config_file:No config file found
(MainThread:INFO:11/28/2018 11:08:21 AM:33:log_file.py:logging_to_console_and_syslog:hostname=sriramsridhar-HP-EliteBook-8460p
 containerID=
 Creating Docker image.
(MainThread:INFO:11/28/2018 11:08:21 AM:33:log_file.py:logging_to_console_and_syslog:hostname=sriramsridhar-HP-EliteBook-8460p
 containerID=
 Setting DOCKER_TAG=ssriram1978,DOCKER_IMAGE_NAME=unit_test
(MainThread:INFO:11/28/2018 11:14:48 AM:33:log_file.py:logging_to_console_and_syslog:hostname=sriramsridhar-HP-EliteBook-8460p
 containerID=
 Prune old docker container images.
(MainThread:INFO:11/28/2018 11:14:48 AM:33:log_file.py:logging_to_console_and_syslog:hostname=sriramsridhar-HP-EliteBook-8460p
 containerID=
 Running Docker image.
(MainThread:DEBUG:11/28/2018 11:14:48 AM:396:connectionpool.py:_make_request:http://localhost:None "POST /v1.35/containers/create?name=unit_test HTTP/1.1" 404 58
(MainThread:DEBUG:11/28/2018 11:14:48 AM:41:auth.py:get_config_header:Looking for auth config
(MainThread:DEBUG:11/28/2018 11:14:48 AM:44:auth.py:get_config_header:No auth config in memory - loading from filesystem
(MainThread:DEBUG:11/28/2018 11:14:48 AM:21:config.py:find_config_file:Trying paths: ['/root/.docker/config.json', '/root/.dockercfg']
(MainThread:DEBUG:11/28/2018 11:14:48 AM:28:config.py:find_config_file:No config file found
(MainThread:DEBUG:11/28/2018 11:14:48 AM:104:auth.py:resolve_authconfig:Looking for auth entry for 'docker.io'
(MainThread:DEBUG:11/28/2018 11:14:48 AM:116:auth.py:resolve_authconfig:No entry found
(MainThread:DEBUG:11/28/2018 11:14:48 AM:58:auth.py:get_config_header:No auth config found
(MainThread:DEBUG:11/28/2018 11:14:49 AM:396:connectionpool.py:_make_request:http://localhost:None "POST /v1.35/images/create?tag=latest&fromImage=ssriram1978%2Funit_test HTTP/1.1" 404 116
(MainThread:DEBUG:11/28/2018 11:20:18 AM:21:config.py:find_config_file:Trying paths: ['/root/.docker/config.json', '/root/.dockercfg']
(MainThread:DEBUG:11/28/2018 11:20:18 AM:28:config.py:find_config_file:No config file found
(MainThread:DEBUG:11/28/2018 11:20:18 AM:21:config.py:find_config_file:Trying paths: ['/root/.docker/config.json', '/root/.dockercfg']
(MainThread:DEBUG:11/28/2018 11:20:18 AM:28:config.py:find_config_file:No config file found
(MainThread:INFO:11/28/2018 11:20:18 AM:33:log_file.py:logging_to_console_and_syslog:hostname=sriramsridhar-HP-EliteBook-8460p
 containerID=
 Creating Docker image.
(MainThread:INFO:11/28/2018 11:20:18 AM:33:log_file.py:logging_to_console_and_syslog:hostname=sriramsridhar-HP-EliteBook-8460p
 containerID=
 Setting DOCKER_TAG=ssriram1978,DOCKER_IMAGE_NAME=unit_test
(MainThread:INFO:11/28/2018 11:20:18 AM:33:log_file.py:logging_to_console_and_syslog:hostname=sriramsridhar-HP-EliteBook-8460p
 containerID=
 Prune old docker container images.
(MainThread:INFO:11/28/2018 11:20:18 AM:33:log_file.py:logging_to_console_and_syslog:hostname=sriramsridhar-HP-EliteBook-8460p
 containerID=
 Running Docker image.
(MainThread:DEBUG:11/28/2018 11:20:18 AM:396:connectionpool.py:_make_request:http://localhost:None "POST /v1.35/containers/create?name=unit_test HTTP/1.1" 404 58
(MainThread:DEBUG:11/28/2018 11:20:18 AM:41:auth.py:get_config_header:Looking for auth config
(MainThread:DEBUG:11/28/2018 11:20:18 AM:44:auth.py:get_config_header:No auth config in memory - loading from filesystem
(MainThread:DEBUG:11/28/2018 11:20:18 AM:21:config.py:find_config_file:Trying paths: ['/root/.docker/config.json', '/root/.dockercfg']
(MainThread:DEBUG:11/28/2018 11:20:18 AM:28:config.py:find_config_file:No config file found
(MainThread:DEBUG:11/28/2018 11:20:18 AM:104:auth.py:resolve_authconfig:Looking for auth entry for 'docker.io'
(MainThread:DEBUG:11/28/2018 11:20:18 AM:116:auth.py:resolve_authconfig:No entry found
(MainThread:DEBUG:11/28/2018 11:20:18 AM:58:auth.py:get_config_header:No auth config found
(MainThread:DEBUG:11/28/2018 11:20:18 AM:396:connectionpool.py:_make_request:http://localhost:None "POST /v1.35/images/create?tag=latest&fromImage=ssriram1978%2Funit_test HTTP/1.1" 404 116
(MainThread:DEBUG:11/28/2018 11:20:34 AM:21:config.py:find_config_file:Trying paths: ['/root/.docker/config.json', '/root/.dockercfg']
(MainThread:DEBUG:11/28/2018 11:20:34 AM:28:config.py:find_config_file:No config file found
(MainThread:DEBUG:11/28/2018 11:20:34 AM:21:config.py:find_config_file:Trying paths: ['/root/.docker/config.json', '/root/.dockercfg']
(MainThread:DEBUG:11/28/2018 11:20:34 AM:28:config.py:find_config_file:No config file found
(MainThread:INFO:11/28/2018 11:20:34 AM:33:log_file.py:logging_to_console_and_syslog:hostname=sriramsridhar-HP-EliteBook-8460p
 containerID=
 Creating Docker image.
(MainThread:INFO:11/28/2018 11:20:34 AM:33:log_file.py:logging_to_console_and_syslog:hostname=sriramsridhar-HP-EliteBook-8460p
 containerID=
 Setting DOCKER_TAG=ssriram1978,DOCKER_IMAGE_NAME=unit_test
(MainThread:INFO:11/28/2018 11:20:34 AM:33:log_file.py:logging_to_console_and_syslog:hostname=sriramsridhar-HP-EliteBook-8460p
 containerID=
 Prune old docker container images.
(MainThread:INFO:11/28/2018 11:20:34 AM:33:log_file.py:logging_to_console_and_syslog:hostname=sriramsridhar-HP-EliteBook-8460p
 containerID=
 Running Docker image.
(MainThread:DEBUG:11/28/2018 11:20:34 AM:396:connectionpool.py:_make_request:http://localhost:None "POST /v1.35/containers/create?name=unit_test HTTP/1.1" 404 58
(MainThread:DEBUG:11/28/2018 11:20:34 AM:41:auth.py:get_config_header:Looking for auth config
(MainThread:DEBUG:11/28/2018 11:20:34 AM:44:auth.py:get_config_header:No auth config in memory - loading from filesystem
(MainThread:DEBUG:11/28/2018 11:20:34 AM:21:config.py:find_config_file:Trying paths: ['/root/.docker/config.json', '/root/.dockercfg']
(MainThread:DEBUG:11/28/2018 11:20:34 AM:28:config.py:find_config_file:No config file found
(MainThread:DEBUG:11/28/2018 11:20:34 AM:104:auth.py:resolve_authconfig:Looking for auth entry for 'docker.io'
(MainThread:DEBUG:11/28/2018 11:20:34 AM:116:auth.py:resolve_authconfig:No entry found
(MainThread:DEBUG:11/28/2018 11:20:34 AM:58:auth.py:get_config_header:No auth config found
(MainThread:DEBUG:11/28/2018 11:20:35 AM:396:connectionpool.py:_make_request:http://localhost:None "POST /v1.35/images/create?tag=latest&fromImage=ssriram1978%2Funit_test HTTP/1.1" 404 116
(MainThread:DEBUG:11/28/2018 11:22:33 AM:21:config.py:find_config_file:Trying paths: ['/root/.docker/config.json', '/root/.dockercfg']
(MainThread:DEBUG:11/28/2018 11:22:33 AM:28:config.py:find_config_file:No config file found
(MainThread:DEBUG:11/28/2018 11:22:33 AM:21:config.py:find_config_file:Trying paths: ['/root/.docker/config.json', '/root/.dockercfg']
(MainThread:DEBUG:11/28/2018 11:22:33 AM:28:config.py:find_config_file:No config file found
(MainThread:INFO:11/28/2018 11:22:33 AM:33:log_file.py:logging_to_console_and_syslog:hostname=sriramsridhar-HP-EliteBook-8460p
 containerID=
 Creating Docker image.
(MainThread:INFO:11/28/2018 11:22:33 AM:33:log_file.py:logging_to_console_and_syslog:hostname=sriramsridhar-HP-EliteBook-8460p
 containerID=
 Setting DOCKER_TAG=ssriram1978,DOCKER_IMAGE_NAME=unit_test
(MainThread:INFO:11/28/2018 11:22:33 AM:33:log_file.py:logging_to_console_and_syslog:hostname=sriramsridhar-HP-EliteBook-8460p
 containerID=
 Prune old docker container images.
(MainThread:INFO:11/28/2018 11:22:33 AM:33:log_file.py:logging_to_console_and_syslog:hostname=sriramsridhar-HP-EliteBook-8460p
 containerID=
 Running Docker image.
(MainThread:DEBUG:11/28/2018 11:22:33 AM:396:connectionpool.py:_make_request:http://localhost:None "POST /v1.35/containers/create?name=unit_test HTTP/1.1" 404 58
(MainThread:DEBUG:11/28/2018 11:22:33 AM:41:auth.py:get_config_header:Looking for auth config
(MainThread:DEBUG:11/28/2018 11:22:33 AM:44:auth.py:get_config_header:No auth config in memory - loading from filesystem
(MainThread:DEBUG:11/28/2018 11:22:33 AM:21:config.py:find_config_file:Trying paths: ['/root/.docker/config.json', '/root/.dockercfg']
(MainThread:DEBUG:11/28/2018 11:22:33 AM:28:config.py:find_config_file:No config file found
(MainThread:DEBUG:11/28/2018 11:22:33 AM:104:auth.py:resolve_authconfig:Looking for auth entry for 'docker.io'
(MainThread:DEBUG:11/28/2018 11:22:33 AM:116:auth.py:resolve_authconfig:No entry found
(MainThread:DEBUG:11/28/2018 11:22:33 AM:58:auth.py:get_config_header:No auth config found
(MainThread:DEBUG:11/28/2018 11:22:33 AM:396:connectionpool.py:_make_request:http://localhost:None "POST /v1.35/images/create?tag=latest&fromImage=ssriram1978%2Funit_test HTTP/1.1" 404 116
(MainThread:DEBUG:11/28/2018 11:22:53 AM:21:config.py:find_config_file:Trying paths: ['/root/.docker/config.json', '/root/.dockercfg']
(MainThread:DEBUG:11/28/2018 11:22:53 AM:28:config.py:find_config_file:No config file found
(MainThread:DEBUG:11/28/2018 11:22:53 AM:21:config.py:find_config_file:Trying paths: ['/root/.docker/config.json', '/root/.dockercfg']
(MainThread:DEBUG:11/28/2018 11:22:53 AM:28:config.py:find_config_file:No config file found
(MainThread:INFO:11/28/2018 11:22:53 AM:33:log_file.py:logging_to_console_and_syslog:hostname=sriramsridhar-HP-EliteBook-8460p
 containerID=
 Creating Docker image.
(MainThread:INFO:11/28/2018 11:22:53 AM:33:log_file.py:logging_to_console_and_syslog:hostname=sriramsridhar-HP-EliteBook-8460p
 containerID=
 Setting DOCKER_TAG=ssriram1978,DOCKER_IMAGE_NAME=unit_test
(MainThread:INFO:11/28/2018 11:22:53 AM:33:log_file.py:logging_to_console_and_syslog:hostname=sriramsridhar-HP-EliteBook-8460p
 containerID=
 Prune old docker container images.
(MainThread:INFO:11/28/2018 11:22:54 AM:33:log_file.py:logging_to_console_and_syslog:hostname=sriramsridhar-HP-EliteBook-8460p
 containerID=
 Running Docker image.
(MainThread:DEBUG:11/28/2018 11:22:54 AM:396:connectionpool.py:_make_request:http://localhost:None "POST /v1.35/containers/create?name=unit_test HTTP/1.1" 404 58
(MainThread:DEBUG:11/28/2018 11:22:54 AM:41:auth.py:get_config_header:Looking for auth config
(MainThread:DEBUG:11/28/2018 11:22:54 AM:44:auth.py:get_config_header:No auth config in memory - loading from filesystem
(MainThread:DEBUG:11/28/2018 11:22:54 AM:21:config.py:find_config_file:Trying paths: ['/root/.docker/config.json', '/root/.dockercfg']
(MainThread:DEBUG:11/28/2018 11:22:54 AM:28:config.py:find_config_file:No config file found
(MainThread:DEBUG:11/28/2018 11:22:54 AM:104:auth.py:resolve_authconfig:Looking for auth entry for 'docker.io'
(MainThread:DEBUG:11/28/2018 11:22:54 AM:116:auth.py:resolve_authconfig:No entry found
(MainThread:DEBUG:11/28/2018 11:22:54 AM:58:auth.py:get_config_header:No auth config found
(MainThread:DEBUG:11/28/2018 11:22:54 AM:396:connectionpool.py:_make_request:http://localhost:None "POST /v1.35/images/create?tag=latest&fromImage=ssriram1978%2Funit_test HTTP/1.1" 404 116
(MainThread:DEBUG:11/28/2018 11:23:26 AM:21:config.py:find_config_file:Trying paths: ['/root/.docker/config.json', '/root/.dockercfg']
(MainThread:DEBUG:11/28/2018 11:23:26 AM:28:config.py:find_config_file:No config file found
(MainThread:DEBUG:11/28/2018 11:23:26 AM:21:config.py:find_config_file:Trying paths: ['/root/.docker/config.json', '/root/.dockercfg']
(MainThread:DEBUG:11/28/2018 11:23:26 AM:28:config.py:find_config_file:No config file found
(MainThread:INFO:11/28/2018 11:23:26 AM:33:log_file.py:logging_to_console_and_syslog:hostname=sriramsridhar-HP-EliteBook-8460p
 containerID=
 Creating Docker image.
(MainThread:INFO:11/28/2018 11:23:26 AM:33:log_file.py:logging_to_console_and_syslog:hostname=sriramsridhar-HP-EliteBook-8460p
 containerID=
 Setting DOCKER_TAG=ssriram1978,DOCKER_IMAGE_NAME=unit_test
(MainThread:INFO:11/28/2018 11:23:26 AM:33:log_file.py:logging_to_console_and_syslog:hostname=sriramsridhar-HP-EliteBook-8460p
 containerID=
 Prune old docker container images.
(MainThread:INFO:11/28/2018 11:23:26 AM:33:log_file.py:logging_to_console_and_syslog:hostname=sriramsridhar-HP-EliteBook-8460p
 containerID=
 Running Docker image.
(MainThread:DEBUG:11/28/2018 11:23:26 AM:396:connectionpool.py:_make_request:http://localhost:None "POST /v1.35/containers/create?name=unit_test HTTP/1.1" 404 58
(MainThread:DEBUG:11/28/2018 11:23:26 AM:41:auth.py:get_config_header:Looking for auth config
(MainThread:DEBUG:11/28/2018 11:23:26 AM:44:auth.py:get_config_header:No auth config in memory - loading from filesystem
(MainThread:DEBUG:11/28/2018 11:23:26 AM:21:config.py:find_config_file:Trying paths: ['/root/.docker/config.json', '/root/.dockercfg']
(MainThread:DEBUG:11/28/2018 11:23:26 AM:28:config.py:find_config_file:No config file found
(MainThread:DEBUG:11/28/2018 11:23:26 AM:104:auth.py:resolve_authconfig:Looking for auth entry for 'docker.io'
(MainThread:DEBUG:11/28/2018 11:23:26 AM:116:auth.py:resolve_authconfig:No entry found
(MainThread:DEBUG:11/28/2018 11:23:26 AM:58:auth.py:get_config_header:No auth config found
(MainThread:DEBUG:11/28/2018 11:23:26 AM:396:connectionpool.py:_make_request:http://localhost:None "POST /v1.35/images/create?tag=latest&fromImage=ssriram1978%2Funit_test HTTP/1.1" 404 116
