(MainThread:INFO:11/27/2018 02:58:39 PM:24:log_file.py:logging_to_console_and_syslog:hostname=sriramsridhar-HP-EliteBook-8460p
 containerID=
 DOCKER_TAG=ssriram1978,DOCKER_IMAGE_NAME=unit_test.
(MainThread:DEBUG:11/27/2018 02:58:39 PM:21:config.py:find_config_file:Trying paths: ['/root/.docker/config.json', '/root/.dockercfg']
(MainThread:DEBUG:11/27/2018 02:58:39 PM:28:config.py:find_config_file:No config file found
(MainThread:DEBUG:11/27/2018 02:58:39 PM:21:config.py:find_config_file:Trying paths: ['/root/.docker/config.json', '/root/.dockercfg']
(MainThread:DEBUG:11/27/2018 02:58:39 PM:28:config.py:find_config_file:No config file found
(MainThread:INFO:11/27/2018 02:58:39 PM:24:log_file.py:logging_to_console_and_syslog:hostname=sriramsridhar-HP-EliteBook-8460p
 containerID=
 Creating Docker image.
(MainThread:INFO:11/27/2018 03:06:02 PM:24:log_file.py:logging_to_console_and_syslog:hostname=sriramsridhar-HP-EliteBook-8460p
 containerID=
 Prune old docker container images.
(MainThread:INFO:11/27/2018 03:06:02 PM:24:log_file.py:logging_to_console_and_syslog:hostname=sriramsridhar-HP-EliteBook-8460p
 containerID=
 Running Docker image.
(MainThread:DEBUG:11/27/2018 03:06:02 PM:396:connectionpool.py:_make_request:http://localhost:None "POST /v1.35/containers/create?name=unit_test HTTP/1.1" 404 58
(MainThread:DEBUG:11/27/2018 03:06:02 PM:41:auth.py:get_config_header:Looking for auth config
(MainThread:DEBUG:11/27/2018 03:06:02 PM:44:auth.py:get_config_header:No auth config in memory - loading from filesystem
(MainThread:DEBUG:11/27/2018 03:06:02 PM:21:config.py:find_config_file:Trying paths: ['/root/.docker/config.json', '/root/.dockercfg']
(MainThread:DEBUG:11/27/2018 03:06:02 PM:28:config.py:find_config_file:No config file found
(MainThread:DEBUG:11/27/2018 03:06:02 PM:104:auth.py:resolve_authconfig:Looking for auth entry for 'docker.io'
(MainThread:DEBUG:11/27/2018 03:06:02 PM:116:auth.py:resolve_authconfig:No entry found
(MainThread:DEBUG:11/27/2018 03:06:02 PM:58:auth.py:get_config_header:No auth config found
(MainThread:DEBUG:11/27/2018 03:06:02 PM:396:connectionpool.py:_make_request:http://localhost:None "POST /v1.35/images/create?tag=latest&fromImage=ssriram1978%2Funit_test HTTP/1.1" 404 116
(MainThread:INFO:11/27/2018 03:06:26 PM:24:log_file.py:logging_to_console_and_syslog:hostname=sriramsridhar-HP-EliteBook-8460p
 containerID=
 DOCKER_TAG=ssriram1978,DOCKER_IMAGE_NAME=unit_test.
(MainThread:DEBUG:11/27/2018 03:06:26 PM:21:config.py:find_config_file:Trying paths: ['/root/.docker/config.json', '/root/.dockercfg']
(MainThread:DEBUG:11/27/2018 03:06:26 PM:28:config.py:find_config_file:No config file found
(MainThread:DEBUG:11/27/2018 03:06:26 PM:21:config.py:find_config_file:Trying paths: ['/root/.docker/config.json', '/root/.dockercfg']
(MainThread:DEBUG:11/27/2018 03:06:26 PM:28:config.py:find_config_file:No config file found
(MainThread:INFO:11/27/2018 03:06:26 PM:24:log_file.py:logging_to_console_and_syslog:hostname=sriramsridhar-HP-EliteBook-8460p
 containerID=
 Creating Docker image.
(MainThread:INFO:11/27/2018 03:13:34 PM:24:log_file.py:logging_to_console_and_syslog:hostname=sriramsridhar-HP-EliteBook-8460p
 containerID=
 Prune old docker container images.
(MainThread:INFO:11/27/2018 03:13:35 PM:24:log_file.py:logging_to_console_and_syslog:hostname=sriramsridhar-HP-EliteBook-8460p
 containerID=
 Running Docker image.
(MainThread:DEBUG:11/27/2018 03:13:35 PM:396:connectionpool.py:_make_request:http://localhost:None "POST /v1.35/containers/create?name=unit_test HTTP/1.1" 404 58
(MainThread:DEBUG:11/27/2018 03:13:35 PM:41:auth.py:get_config_header:Looking for auth config
(MainThread:DEBUG:11/27/2018 03:13:35 PM:44:auth.py:get_config_header:No auth config in memory - loading from filesystem
(MainThread:DEBUG:11/27/2018 03:13:35 PM:21:config.py:find_config_file:Trying paths: ['/root/.docker/config.json', '/root/.dockercfg']
(MainThread:DEBUG:11/27/2018 03:13:35 PM:28:config.py:find_config_file:No config file found
(MainThread:DEBUG:11/27/2018 03:13:35 PM:104:auth.py:resolve_authconfig:Looking for auth entry for 'docker.io'
(MainThread:DEBUG:11/27/2018 03:13:35 PM:116:auth.py:resolve_authconfig:No entry found
(MainThread:DEBUG:11/27/2018 03:13:35 PM:58:auth.py:get_config_header:No auth config found
(MainThread:DEBUG:11/27/2018 03:13:35 PM:396:connectionpool.py:_make_request:http://localhost:None "POST /v1.35/images/create?tag=latest&fromImage=ssriram1978%2Funit_test HTTP/1.1" 404 116
